Para inicar o curso, criamos um novo projeto e dentro deste 
projeto, uma nova classe chamada Fluxo:

public class Fluxo {

    public static void main(String[] args) {
        System.out.println("Ini do main");
        metodo1();
        System.out.println("Fim do main");
    }

    private static void metodo1() {
        System.out.println("Ini do metodo1");
        metodo2();
        System.out.println("Fim do metodo1");
    }

    private static void metodo2() {
        System.out.println("Ini do metodo2");
        for(int i = 1; i <= 5; i++) {
            System.out.println(i);
        }
        System.out.println("Fim do metodo2");
    }
}

ao executar noso projeto, no console aparecerá:
 - "Ini do main", chamando logo em seguida e acessando o metodo1();
 - "Ini do metodo1", chamando logo em seguida e acessando o metodo2();
 - "Ini do metodo 2", que na sequência, será executado um laço de repetição, no qual a 
 variável i começa em 1 e vai até 5. Essa mensagem será exibida até o final do laço.

Para cada finalização de execução do método, será impresso uma mensagem de conclusão, na seguinte ordem:
 - Fim do metodo2;
 - Fim do metodo1;
 - Fim do main;


Ate o momento podemos reparar que não temos orientação a objetos, mas independente do 
paradigma de programação, usamos uma pilha de execução. 

para entendermos melhor:
Um programa Java sempre começa no metodo main(). A pilha ou stach existe para organizar 
a execução do código, lembrando que ainda precisa ser executado.

O Java sempre irá procurar primeiro pelo método main(). Depois, ele cria a pilha e coloca o bloco
de código dentro de outro, na pilha. Em seguida, o código do método1() é inserido na pilha

** A pilha existe para executar algo e lembrar o que ainda precisa ser executado.


Agora o método1() entra na pilha de execução.
Reparem que o main() ainda não foi finalizado, porém, elen não está em execução agora, 
apenas o método que está no topo da pilha que estará sendo executado.

A partir do métodos1(), vem a chamada do método2() e todo o bloco de código é 
jogado dentro da pilha.

Demonstrando:


Pilha(Stack)

|           |
|           |
|           |
|           |
| metodo2() |
| metodo1() |
|__main()___|


Console:
Ini do main
Ini do metodo1
Ini do metodo2
1
2
3
4
5
Fim do metodo2




Os métodos main() e metodo1() estão separados, pois ainda tem código
a ser executado, no caso, as linhas do "Fim do metodo1" e "Fim do main".

O metodo2() está sendo executado, pois, está no tipo da pilha, 
que conseguirá removê-lo assim que terminar de executá-lo, quando 
não houver mais nada para executar deste metodo.


Demonstrando:


Pilha(Stack)

|           |
|           |
|           |
|           |
|           |
| metodo1() |
|__main()___|


Console:
Ini do main
Ini do metodo1
Ini do metodo2
1
2
3
4
5
Fim do metodo2
Fim do metodo1


Quem está executando agora é o metodo1(). O que sobrou nele é a linha que exibe a 
mensagem "Fim do metodo1". Depois que ele acaba, a pilha remove e continua com a main(),
que ficou por último.


Demonstrando:


Pilha(Stack)

|           |
|           |
|           |
|           |
|           |
|           |
|__main()___|


Console:
Ini do main
Ini do metodo1
Ini do metodo2
1
2
3
4
5
Fim do metodo2
Fim do metodo1
Fim do main


Voltando a main(), é exibida a linha que imprime "Fim do main". Com isso, 
é finalizado e retirado da pilha.



Demonstrando:


Pilha(Stack)

|           |
|           |
|           |
|           |
|           |
|           |
|___________|


Console:
Ini do main
Ini do metodo1
Ini do metodo2
1
2
3
4
5
Fim do metodo2
Fim do metodo1
Fim do main


Ao acabar os métodos da pilha, o Java entende que o processo foi encerrado.

A pilha existe para saber qual método está sendo executado no momento, ou seja,
o que está no topo e lembrar quais ainda precisam ser executadas.



Depuração:


Ao debugarmos o programa, será possível ver as mudanças em tempo real, 
em uma velocidade que podemos acompanhar. Para isso, no eclipse
com o botão direito em "main() > Debug As > Java Application".

No debug o main() é o primeiro método que está sendo executado.
Ao colocar um breakpoint e ter acesso ao mesmo, o programa ficará parado
neste ponto, assim inicia a analise em debug, assim, 
o java fica aguardando as instruções, para avanço de linha a linha 
usamos a opção Step Over no eclipse, assim vai indo a execução linha a linha,
ajudando assim em uma análise mais clinica.



Exceções: O que são e para que servem?

As exceções são problemas que acontecem na hora de compilar o código. Considerando que existe uma 
variedade imensa, elas possuem nomes explicativose, as vezes, mostram claramente o motivo de seu surgimento, 
falicitando a identificação delas.


Um exemplo de exceção:


public class TesteContas {

    public static void main(String[] args) {

        //instancia para testar exceção!!!!
        ContaCorrente conta = null;
        outra.deposita(200.0);

        //instancia da conta corrente
        ContaCorrente cc = new ContaCorrente(111, 111);
        cc.deposita(100.0);

        //instancia da conta poupança
        ContaPoupanca cp = new ContaPoupanca(222, 222);
        cp.deposita(200.0);
    }
}


Console: 
Exception in thread "main" java.lang.NullPointerException
        at TesteContas.main(TesteContas.java:7)
        
        
        
É possível verificar que essa referência não foi inicializada corretamente.
Em alguns casos, não conseguimos enxergar se essa referência foi inicializada 
de forma correta ou não, o que pode ocasionar a exibição desse problema no console.

Mas, qando isso acontece, o desenvolvedor precisa entender o que houve e o que 
ele fez de errado. Considerando que a exceção se chama NullPointerException e nós inicializamos a váriavel
conta como nula, deduzimos que ela faz referência à váriavel. 


Outro exemplo: 
Dentro do main, colocaremos a seguinte operação:

public class TesteContas {
    public static void main(String[] args) {

        int a = 3;
        int b = a / 0;
    }
}

Aqui não ocorrerá erro de sintaxe, porém, o que vai acontecer?

Console:

Exception in thread "main" java.lang.ArithmeticException: / by zero
        at TesteContas.main(TesteContas.java:7)
        
/ by zero, ou seja, nem o Java consegue dividir algo por zero. Esse tipo de problema
não deveria acontecer, mas em um ambiente mais complexo, é realmente mais díficil prever.


A primeira motivação é que erros e exceções acontecem. Portanto, precisamos saber lidar com elas.
Mais um exemplo, para praticar:

Na classe Conta, existe um método saca(), que recebe um valor como parâmetro:


public boolean saca(double valor) {
    if(this.saldo >= valor) {
        this.saldo -= valor;
        return true;
    } else {
        return false;
    }
}

Se caso funcionar, devolve true, caso contrário, devolve false. Nessa implementação, partiremos 
do príncipio de que existe apenas um motivo para que o saque não funcione: saldo insuficiente.
Considerando um cenário real, existem mais motivos que impedem o saque. 
Pode ser o limite diário, o horário comercial, o banco pode estar fechado no momento
e achar que nós poderíamos fraudar ou qualquer outro motivo.

O método retorna somente "Funcionou" ou "Não funcionou", mas queremos que ele nos retorne
motivos específicos quando não funcionar. Para isso, usamos as exceções:

Na nossa classe Fluxo, vamos verificar como isso funciona junto à pilha:


Introduzindo um erro simples no metodo2() para nos ajudar a entender melhor. Declararemos
uma nova variável e a dividimos por zero:

private static void metodo2() {
    System.out.println("Ini do metodo2");
    for(int i = 1; i <= 5; i++) {
        System.out.println(i);
        int a = i / 0;
    }
    System.out.println("Fim do metodo2");
}


Obviamente, não é uma boa idéia, mas é importante ver como realmente entendemos essa 
exceção.

Ao executar, no console aparecerá assim:

Ini do main
Ini do metodo1
Ini do metodo2
1
Exception in thread "main" java.lang.ArithmeticException: / by zero
        at Fluxo.metodo2(Fluxo.java:19)
        at Fluxo.metodo1(Fluxo.java:11)
        at Fluxo.main(Fluxo.java:5)
        

Logo abaixo de ArithmeticException, conseguimos verificar a pilha de execução.
Em cima do main, temos o metodo1, acima dele, temos o metodo2.


Podemos observar que o Console de Execução com Exceção é semelhante ao normal, até 1. 
Além da exibição do nome (ArithmeticException) e da mensagem (/ by zero), apó o 1, 
a execução muda = por causa da exceção - é exibido a pilha de execução.

Assim, podemos perceber que as exceções mudam o fluxo, pois eles fazem parte do controle dele. Mas, 
porque mudou o fluxo? A partir do momento em que o metodo2() entrou no laço, 
apareceu a exceção " Não foi possível realizar a divisão por 0 ". 


Para acessibilidade: 
Podemos imaginar a pilha de execução, como um copo que recebe várias 
camadas, chamadas de métodos. A ordem de surgimento delas está de acordo com o método
que é chamado. Como todo método é chamado a partir do main(), ele sempre estará no fundo
do copo, pois é sempre o primeiro.

A main(), por usa vez, chama o método1(), que chamará o método2(). 
Como o método2() foi o último a ser chamado, ele está no topo do copo. 
A exceção cai no método2() e como ele não tem nenhum bloco de código
que possa tratar essa bomba, o método2() sai do copo, e cai na função
anterior, ou seja, no método1().

Por sua vez, o metodo1() também não possui o bloco de código para tratar essa exceção e 
por isso, o método sai da pilha, transferindo a exceção para main(), que assim como 
os anteriores, não possui tratamento para a exceção, sendo obrigada a sair da pilha de execução, que
será jogada no console.

Resumindo: sabemos que existem exceções e que elas mudam o fluxo. 
Se soluções não forem encontradas dentro da pilha de execução, 
elas serão impressas no console.



Try Catch

Chegamos ao ponto que exceções possuem nomes e elas acontecem
porque algo deu errado ou inesperado, podendo até mudar o fluxo
de execução da aplicação.


Para tratarmos uma exceção, é preciso sinalizar a máquina virtual 
que isso pode acontecer, por meio de um código específico (try).
Assim, ela entenderá que deve tentar executar esse código, entre chaves({})
e com mais cautela.

Exemplo:

private static void metodo2() {
    System.out.println("Ini do metodo2");
    for(int i = 1; i <= 5; i++) {
        System.out.println(i);
        try {
            int a = i / 0;
        }
    }
}

Desta forma, o códiugo ainda nao irá compilar, porque precisamos avisar para a máquina virtual
qual a exceção pode acontecer. Para isso, utilizaremos um novo bloco de código, 
por meio de catch, sinalizando que queremos capturar um problema. No caso, ArithmeticException.

try {
    int a = i / 0;
} catch (ArithmeticException ex) {

}

Após o nome da exceção, inserimos uma váriavel.

Desta forma, o bloco try sinaliza o código int a = i / 0 como perigoso e em caso de 
exceção, a capturamos e executaremos no bloco seguinte, por meio de catch. Dentro dele, 
imprimiremos o seguinte:

try {
    int a = i / 0;
} catch (ArithmeticException ex) {
    System.out.println("ArithmeticException");
}


ao executar desta forma, o resultado será: 

Ini do main
Ini do metodo1
Ini do metodo2
1
ArithmeticException
2
ArithmeticException
3
ArithmeticException
4
ArithmeticException
5
ArithmeticException
Fim do metodo2
Fim do metodo1
Fim do main

Agora podemos notar que temos um bloco de código que sabe resolver a questão.
A exceção foi capturada por catch e no console, foi impresso System.out.println("ArithmeticException").
No entanto, logo depois apareceu o 2, ou seja, a VM continuou com o laço e voltou para a execução
normal. Isso é o que acontece em cada iteração. 

Agora que já sabemos como resolver alguma exceção, utilizando tryCatch, não queremos mais 
que ele fique dentro do laço, considerando que ele não precisa estar lá. 
Transferindo este bloco para a hora da chamada do método2(), ficaria assim:

private static void metodo1() {
    System.out.println("Ini do metodo1");
    try {
        metodo2();
    } catch(ArithmeticException ex) {
        System.out.println("ArithmeticException");
    }
    System.out.println("Fim do metodo1");
}


e a saída seria a seguinte: 

Ini do main
Ini do metodo1
Ini do metodo2
1
ArithmeticException
Fim do metodo1
Fim do main

Podemos observar que houve um erro, na primeira iteração
do laço dentro do metodo2(). Temos algum código no metodo2() que saiba
resolver esta questão? Não!
Desta forma, o java saiu abruptamente da linha int a = i/0 e voltou para a chamada
do metodo2(), dentro do tryCatch. Repare que na saída não apareceu "Fim do metodo2", 
porque ele foi descartado e então, voltamos o metodo1(), no qual temos um código para 
resolver ArithmeticException.

Capturamos a exceção da pilha e imprimimos "ArithmeticException" e logo depois, 
voltou à execução normal, imprimindo "Fim do metodo1" e "Fim do main".




Variação do Catch

Sabemos que temos uma exceção do tipo ArithmeticException. A variável ex é uma 
referência e com isso, podemos dizer que exceções também são objetos. Então, podemos 
usar a referência para chamar algum método público da classe.
Pegando o método getMessage(), com qual conseguiremos pegar a informação
apresentada no console, por exemplo, a mensagem / by zero.
Depois de pegá-la, remos guarda-la em uma String e mostra-lá após
"ArithmeticException".

public static void main(String[] args) {
    System.out.println("Ini do main");
    try {
        metodo1();
    } catch(ArithmeticException ex) {
        String msg = ex.getMessage();
        System.out.println("ArithmeticException " + msg);
    }
    System.out.println("Fim do main");
}

o trecho acima, resulta, após ser compilado e executado em:

Ini do main
Ini do metodo1
Ini do metodo2
1
ArithmeticException / by zero
Fim do main

há muito mais que podemos fazer, da mesma forma que a exceção se lembra 
da mensagem, ela também se lembra por onde passou e deixou seu rastro.
Para mostrá-lo, usaremos o método printStackTrace():

Desta forma, entendemos que ex é uma referência e o tipo da referência é o nome da classe da exceção.
Parte do tratamento dela é saber trabalhar com a referência. 
Normalmente, não precisamos saber muito sobre ex. 
basta sabermos que getMessage() é um método importante para descobrir a mensagem original
e que o printStackTrace() pode ser útil também.

Criando uma classe Conta, com método deposita() vazio.
Criando uma referência da classe Conta nula, ou seja, ela apontará
para nenhum objeto. E chamaremos o metodo1() a partir dela.

Outro exemplo de exception:

private static void metodo2() {
    System.out.println("Ini do metodo2");
    for(int i = 1; i <= 5; i++) {
        System.out.println(i);
        //int a = i / 0;
        Conta c = null;
        c.deposita();
    }
    System.out.println("Fim do metodo2");
}


Ao executar o codigo, já sabemos que vai dar erro, pois a referência c está nula.
A saída dessa execução será:

Ini do main
Ini do metodo1
Ini do metodo2
1
Exception in thread "main" java.lang.NullPointerException
            at Fluxo.metodo2(Fluxo.java:27)
            at Fluxo.metodo1(Fluxo.java:17)
            at Fluxo.main(Fluxo.java:6)
            

Sabemos que existe um código main capaz de resolver ArithmeticException.
Entretanto, podemos perceber que não apareceu o "Fim do main" na saída,
como no exemplo anterior, ou seja, não conseguimos pegar a exception
por meio de um catch(). Isso aconteceu porque fizemos um catch específico,
que funciona somente para ArithmeticException e o nosso problema se 
chama NullPointerException.

Para resolver é simples, basta mudar o nome da exceção dentro do catch.      
mas sabemos que o código pode criar outros tipos de exceções, além 
de ArithmeticException, podemos manter a exceção desse catch e criar um segundo
para a exceção é: NullPointerException();

public static void main(String[] args) {
	    System.out.println("Ini do main");
	    try {
	        metodo1();
	    } catch(ArithmeticException ex) {
	        //String msg = ex.getMessage();
	        //System.out.println("ArithmeticException " + msg);
	        ex.printStackTrace();
	    } catch (NullPointerException ex) {
	    	String msg = ex.getMessage();
	    	System.out.println("NullPointerException ---> " + msg);
	    	//ex.printStackTrace();
		}
	    System.out.println("Fim do main");
	}

qualquer exceção, tem em si o método getMessage();

A mensagem pelo getMessage() foi null, ou seja, segundo bloco de catch foi
chamado, então, podemos ter quantos blocos quisermos, desde que eles sejam
específicos o suficiente.

A partir do Java 1.7, chegou uma versão variada do catch. Em vez de 
repetir vários blocos de catch, podemos colocar um pipe, que sgnifica "ou"


Pontos importantes e estudados no Capítulo 02:
 - O que são exceções, para que servem e porquê utilizá-las.
 - Como analisar o rastro de exceções, ou stacktrace.
 - Tratar exceções com os blocos try-catch.
 - Manipular uma exceção lançada dentro do bloco catch.
 - Tratar múltiplas exceções com mais de um bloco catch ou 
 usando Multi-Catch utilizando o pipe (|).
 
 
 
 Capítulo 03 -> 01 Revisão
 
 o Java organiza a execução de uma pilha, que sempre 
 começa com o método main() e pode crescer e diminuir 
 de tamanho, dependendo da quantidade de métodos que forem executados.


Assim como várias outras linguagens, o Java utiliza essa 
pilha de execução, que é importante para entendermos o "rastro" 
da exceção. O nosso principal objetivo é entender que quando 
acontece a exceção, ela se lembra por quais métodos ela passou.

Alguns eventos excepcionais e imprevistos podem aparecer em 
nossa aplicação. Portanto, precisamos saber lidar com isso, 
entendendo a exceção, suas mensagens e o seu rastro.

Para o Fluxo:

Vimos que exceção muda o fluxo. Se o método não for capaz de 
tratá-la, o fluxo de execução sai abruptamente dele e vai 
para o próximo, até encontrar algum método que saiba tratá-la.

para o Try Catch:

Para lidar com essa Exception e voltar para uma execução normal, 
podemos utilizar o try-catch. Com o try, alertamos a máquina virtual, 
e com o catch, definimos qual exceção pode acontecer.

A referência ex declarada no bloco catch, é um objeto onde podemos 
chamar métodos como o getMessage() para receber a mensagem, 
e o printStackTrace() para mostrar o rastro da pilha.



Lançando exceções

Criando nossas próprias exceções, anteriormente, vimos que elas podem ocorrer 
quando algo inesperado acontece no código, por exemplo, uma divisão por zero ou uma
referência nula.

Mas, sabendo que essas exceções não deveriam acontecer. 
Deveríamos programar de forma correta, 
evitando-as, todavia, existem casos em que as exceções nos ajudarão muito.

Na classe Fluxo, retornaremos ao try Catch e usaremos a referência ex
para chamar algum método que se comunique com o objeto. Se ex é uma 
referência, então NullPointerException é um tipo baseado em uma classe.

Criaremos um objeto da classe ArithmetcException e o guardaremos na referência
exception:

private static void metodo2() {
   System.out.println("Ini do metodo2");

   ArithmeticException exception = new ArithmeticException();

   System.out.println("Fim do metodo2");
 
}

Se criarmos um objeto da classe ArithmeticException, também criamos uma exceção?
Não, nós somente criarmos o objeto e ainda falta um passo para isso.

A referência exception aponta para ArithmeticExceptionm que está no HEAP (memória
de objetos), desta forma, precisamos falar para o Java pegar esse objeto, transformar
em uma exceção e "jogar" na pilha. 
O verbo "jogar", em inglês é throw, então, vamos "jogar" o objeto a partir da 
referência exception:

private static void metodo2() {
    System.out.println("Ini do metodo2");
    ArithmeticException exception = new ArithmeticException();
    throw exception ;
    System.out.println("Fim do metodo2");
}

O Java reconhece que quando jogamos uma esceção, saímos abruptamente do código.
Se isso acontecer, não é possível executar a linha que mostra "Fim do método2". 
Por isso, esta linha ficará comentada somente para compilar e demonstrar 
a execução:

private static void metodo2() {
    System.out.println("Ini do metodo2");
    System.out.println("-------------------------");
    
    //criação de objeto
    ArithmeticException exception = new ArithmeticException();
    throw exception;
    
    //System.out.println("-------------------------");
    //System.out.println("Fim do metodo2");
}


e ao executar, obtemos a seguinte saída no console:

Ini do main
Ini do metodo1
Ini do metodo2
Exception null
java.lang.ArithmeticException
        at Fluxo.metodo2(Fluxo.java:24)
        at Fluxo.metodo1(Fluxo.java:17)
        at Fluxo.main(Fluxo.java:6)
Fim do main

Podemos analisar que não foi impresso o "Fim do metodo1" e por esse motivo, 
sabemos que saímos abruptamente do método. Quando main recebe ArithmeticException, 
pega essa exceção e mostra a mensagem, alterando agora a mensagem, 
retornará "deu errado":

private static void metodo2() {
    System.out.println("Ini do metodo2");
    System.out.println("-------------------------");
    
    //criação de objeto
    ArithmeticException exception = new ArithmeticException("deu errado");
    throw exception;
    
    //System.out.println("-------------------------");
    //System.out.println("Fim do metodo2");
}

Será que é possível transformar qualquer objeto na pilha?
Vamos criar um objeto do tipo Conta:

Podemos observar que não foi possível fazer o throw c na pilha, 
pois só é possível com exceção. 

Normalmente, quando queremos jogar uma exceção, fazemos isso de maneira mais enxuta, 
sem guardar a referência

private static void metodo2() {
        System.out.println("Ini do metodo2");
        System.out.println("-------------------------");
        
        //criação de objeto
        throw new ArithmeticException();
        
        //System.out.println("-------------------------");
        //System.out.println("Fim do metodo2");
    }


essa é a forma mais comum de encontrarmos no dia a dia.


Hierarquia de exceções:

 - (ArithmeticException e NullPointerException) extends RuntimeException
 - RuntimeException extends Exception
 - Exception extends Throwable


Com throw, jogamos o objeto da exceção na pilha, e isso só funciona 
com exceções. Mas, por quê? Vamos ver o que tem dentro da 
classe ArithmeticException:

public class ArithmeticException extends RuntimeException {
    private static final long serialVersionUID = 2256477558314496007L;

    public ArithmeticException() {
        super();
    }

    public ArithmeticException(String s) {
        super(s);
    }
}

Aqui temos um ótimo exemplo de herança, não é mesmo? Temos também dois 
construtores: um vazio e outro que recebe uma String, que representa a 
mensagem. O primeiro super() significa que estamos subindo a hierarquia 
para chamar o construtor da classe mãe. Já o segundo, repassa a mensagem 
do tipo String do construtor para o construtor da classe mãe.

Também podemos encontrar nessa classe, um atributo estático serialVersionUID, 
que representa uma identificação da classe, um valor único.

Chamaremos a classe mãe da ArithmeticException, a RuntimeException:

public class RuntimeException extends Exception {
    static final long serialVersionUID = -7034897190745766939L;

    public RuntimeException() {
        super();
    }

    public RuntimeException(String message) {
        super(message);
    }

    public RuntimeException(String message, Throwable cause) {
        super(message, cause);
    }

    public RuntimeException(Throwable cause) {
        super(cause);
    }

    protected RuntimeException(String message, Throwable cause, boolean enableSuppression, boolean writableStackTrace) {
        super(message, cause, enableSuppression, writableStackTrace);
    }
}


Repare que essa classe também possui uma classe mãe, a Exception, 
além de construtores. Voltando à classe Fluxo, vemos que não importa o 
tipo da referência ex, sendo ArithmeticException ou NullPointerException, 
nós conseguimos chamar o método getMessage(), mesmo que nenhum desses 
dois tipos tenha o método getMessage().

A classe RuntimeException também não tem esse método. A classe Exception 
tem vários construtores, mas nenhum sinal desse método. Essa classe 
estende ou herda de Throwable. Usamos a palavra throw para jogar o 
objeto da exceção na pilha e ela não funciona para classes e objetos que 
não sejam exceções.
Para jogar um objeto na pilha, a classe precisa estender Throwable.

Ainda dentro de Throwable, encontramos o atributo detailMessage que 
especifica detalhes, as mensagens. Entretanto a classe Throwable é 
enorme, e nem tudo o que ela possui nos interessa. Por essa razão, 
para saber os membros dessa classe, utilizamos o atalho "Ctrl + O".

Agora conseguimos então visualizar os seus membros, 
os métodos e atributos. E então, encontramos os métodos getMessage() e 
printStackTrace(). Ou seja, todos os métodos do mundo de exceções foram 
implementados na classe mãe Throwable

Podemos concluir que concluímos que para criarmos a nossa própria exceção, 
]basta nos colocarmos dentro dessa hierarquia. Para começar, criaremos 
MyException, que estende a classe RuntimeException.

Se implementarmos os construtores dentro da nova classe que criamos: MyException, 
Temos o rastro da pilha e o nome da exceção iguais a ArithmeticException e 
NullPointerException. Mas uma coisa mudou. Repare que não apareceu "Fim do main". 
Essa linha não foi executada porque não capturamos a exceção!

Em catch, só estamos capturando as exceções ArithmeticException e 
NullPointerException, e não MinhaExcecao. Então, é preciso adicionar
 mais um pipe (|) para conseguirmos colocar mais um tipo de exceção:
 
 public static void main(String[] args) {
    System.out.println("Ini do main");
    try {
        metodo1();
    } catch(ArithmeticException | NullPointerException | MyException ex) {
        String msg = ex.getMessage();
        System.out.println("Exception " + msg);
        ex.printStackTrace();
    }
    System.out.println("Fim do main");
}


Entendendo Erros:

Como podemos ver anteriormente, a classe topo é a Throwable, onde tem por exemplo
getMessage() declarado. A Exception e RuntimeException só possuem construtores.
Mas mesmo assim, nós estendemos RuntimeException, assim como ArithmeticException e
NullPointerException;

"Há, mas não seria mais fácil cortar caminho e buscar estender diretamente 
o Throwable?"
Considerando que RuntimeException e Exception so possuem construtores.
Totalmente errado!

Existe uma hierarquia de classe que estende Throwable, como a classe Error.
Entretanto nós não a conhecemos muito bem, porque é uma hierarquia pensada para 
desenvolvedores de máquina virtual. Desenvolvedores Java, não trabalha com classes 
diretamente. Quem cria e "joga" esses objetos na pilha é a VM, quando 
algo muito grave acontece.


A VM pode não conseguir mais executar o código porque não tem mais memória 
suficiente e então ela jogará um erro internamente.


Para simular um erro bem famoso, faremos uma nova classe, chamada FluxoComError
 e dentro desta classe, reformulamos o metodo2() e o chamamos dentro dele mesmo:
 
private static void metodo2() {
   System.out.println("ini do metodo 2");
   metodo2();
   System.out.println("fim do metodo 2");
}


Quando o Java entrar no metodo2(), imprimirá a mensagem "ini do metodo2"
e vai chamar de novo e a pilha irá crescer, pois o metodo2() 
ficará se chamando.

ao executarmos o código, veremos várias vezes linhas de "ini do metodo2", 
porque o método fica chamando ele mesmo. Essa ação se repete até 
não ter mais espaço na pilha. Nesta execução, temos um dos erros mais famosos
o StackOverflowError.

Existe uma hierarquia de classes utilizada internamente pela Máquina virtual, 
mas ainda temos a seguinte questão:

Qual a diferença entre Exception e RuntimeException? Por que não podemos
eliminá-las?


 - Checked e unchecked:

Para acessibilidade: 
A hierarquia abordada contém uma classe mãe chamada Throwable. 
A partir dela, formam-se duas categorias: uma para exceções onde 
o desenvolvedor pode gerenciar e uma outra categoria voltada 
para erros da máquina virtual.

As exceções ArithmeticException, NullPointerException e MinhaException 
herdam de RuntimeException, que por sua vez, herda de Exception 
e Exception herda de Throwable, formando a primeira categoria de 
exceções. Já a segunda categoria de erros possui StackOverflowError, 
que herda de VirtualMachineError, que herda de Error, 
que herda de Throwable, formando a segunda categoria.

Lembrando que a segunda categoria é a hierarquia utilizada pela 
máquina virtual. Entretanto, o que nos interessa é a hierarquia 
da Exception, a primeira categoria. E por que a classe 
ArithmeticException não estende diretamente da classe Exception? 
Por que a MyException não estende a classe Exception?

Acessaremos a classe MyException, e estenderemos diretamente 
da classe Exception. Repare que o código já para de compilar. 
Apareceu algum problema.

Existe um erro de compilação na linha do throw new 
MyException("deu muito errado"). Se retirarmos a palavra throw 
dessa frase, o problema desaparecerá. O problema é que o Java 
faz uma separação. Duas categorias de exceções são criadas dentro 
das exceções para o desenvolvedor de aplicações.

A primeira categoria é a que estende de RuntimeException, e a outra é 
a que estende diretamente de Exception. O compilador faz uma 
verificação sintática para ver quem dá throw nessas exceções. 
Isso significa que a exceção exige que fique explícito na 
assinatura do método que estamos jogando a exceção:

private static void metodo2() throws MyException {
        System.out.println("Ini do metodo2");
        System.out.println("-------------------------");
        
        throw new MyException("deu errado");
        
        //System.out.println("-------------------------");
}

Dessa forma, dizemos que o método joga uma exceção do tipo MyException. 
Agora, o método volta a compilar. Quando usamos throw new de uma exceção 
que estende diretamente da classe Exception, o compilador exige que coloquemos, 
explicitamente, throws na assinatura do método.

A ideia é que o "perigo" — a exceção — fique explícita na assinatura do método. 
Com isso, temos duas categorias novas de Exception. A primeira é a que estende 
de RuntimeException e se chama Unchecked. A segunda categoria é a que estende 
diretamente de Exception, chamada de Checked.


Por que checked e unchecked?

Na categoria Unchecked, o compilador não dá muita importância. 
Se dermos throws ou não, ele não toma atitude, ou seja, ele não verifica — 
unchecked (não verificado pelo compilador).

Já a categoria Checked é verificada pelo compilador. 
No metodo2(), somos obrigados a colocar throws na assinatura do 
método, pois a exceção do tipo MyException estende diretamente de 
Exception e, por isso, é verificada pelo compilador.

Repare que a chamada do metodo2(), no metodo1(), não compila mais. 
Agora, isso acontece porque o compilador detecta que existe uma exceção checked 
na assinatura e, por isso, é necessário também deixar explícito o throws MyException 
na assinatura do metodo1().

private static void metodo1() throws MyException {

}


Podemos colocar throws no método ou transferir a exceção para a categoria unchecked. 
Repare que colocamos throws nos dois métodos, mas não o colocamos em main() e, 
mesmo assim, o código compilou. Isso aconteceu porque estamos fazendo um tratamento 
da exceção com o try-catch. Ou seja, temos duas formas de resolver uma exceção checked.

Ou colocamos o throws na assinatura, ou fazemos um try-catch.

Fazendo um try-catch, o compilador não se manifestou, 
pois estamos resolvendo o problema da exceção. 
Se estamos resolvendo, não é necessário colocar o throws na assinatura do método. 
Considerando que foi só um exemplo, vamos deixar como estava, pois já temos 
um try-catch em main().

O conceito de exceções existe em várias linguagens,mas o checked e o unchecked
 é algo específico do mundo Java.
 
 
 
 Existe uma hierarquia grande de classes que representam exceções. 
 Por exemplo, ArithmeticException é filha de RuntimeException, que herda de 
 Exception, que por sua vez é filha da classe mais ancestral das exceções, 
 Throwable. Conhecer bem essa hierarquia significa saber utilizar exceções 
 em sua aplicação.
 
Throwable é a classe que precisa ser extendida para que seja possível 
jogar um objeto na pilha (através da palavra reservada throw)

É na classe Throwable que temos praticamente todo o código relacionada às 
exceções, inclusive getMessage() e printStackTrace(). Todo o resto da 
hierarquia apenas possui algumas sobrecargas de construtores para comunicar 
mensagens específicas

A hierarquia iniciada com a classe Throwable é dividida em exceções e erros. 
Exceções são usadas em códigos de aplicação. Erros são usados exclusivamente 
pela máquina virtual.

Classes que herdam de Error são usadas para comunicar erros na máquina virtual.
 Desenvolvedores de aplicação não devem criar erros que herdam de Error.
 
StackOverflowError é um erro da máquina virtual para informar que a pilha de 
execução não tem mais memória.

Exceções são separadas em duas grandes categorias: aquelas que são obrigatoriamente
 verificadas pelo compilador e as que não são verificadas.
As primeiras são denominadas checked e são criadas através do pertencimento a uma
 hieraquia que não passe por RuntimeException.
As segundas são as unchecked, e são criadas como descendentes de RuntimeException.


Cap05 - 01 Capturando qualquer exceção

Existe uma diferença entre as exceções Checked e Unchecked, 
dependendo de qual classe estendemos. se estendemos de RuntimeExcpetion,
temos uma exceção do tipo Unchecked, ou seja, o compilador não toma
nenhuma atitude. Tendo throw ou não, ele não se importa.

Se estendermos diretamente da classe Exception, o compilador ficará 
de olho e nos obrigará a colocar throws na assinatura do método, 
para sinalizar quem chama o método, que ele é perigoso
ou tratar a exceção no próprio método com o try-catch. Essa 
exceção é do tipo checked.

Obs.: Na hora de executar o codigo, não tem diferença! 
Todos são exceções que caem na pilha.

Mas para que serve o checked e o unckeded.

Essa é uma pergunta díficil, pois o significado de Checked e Unchecked 
para o nosso código, mudou durante a vida do Java.


A polêmica das exceções está relacionada ao Checked. Hoje, 
existem aplicações que simplesmente não usam exceções desse tipo, 
e é muito comum utilizar bibliotecas que só têm exceções Unchecked, 
nas quais o compilador não nos obriga a tomar alguma atitude.

Então, para que serve checked, considerando que, atualmente, 
a maioria utiliza Unchecked?

utilizando nossa classe Conta, iremos demonstrar o porque:

public class Conta {
    void deposita() {

    }
}

Na assinatura do método deposita(), colocaremos throws e a exceção 
criada. Lembrando que a exceção que criamos MyException() é do tipo Checked.


public class Conta {
    void deposita() throws MyException{

    }
}

Repare que não é necessário fazer alterações no método, pois, 
ele já estará compilando. Vamos criar uma nova classe, instanciar a 
Conta e chamar o método.


public class TestaContaComExceptionChecked {

	public static void main(String[] args) {
		
		Conta c = new Conta();
		c.deposita();
	}

}

Como o método deposita() é vazio, nenhuma exceção será criada. 
Mas, basta colocar o throws MyException na assinatura e o compilador 
saberá que o método tem uma exceção do tipo Checked na sua assinatura. 
Por isso, temos que tomar uma atitude: ou colocamos throws MyException 
na assinatura de main(), ou utilizamos try-catch. Se escolhermos a 
segunda opção, obteremos o seguinte:

public class TestaContaComExceptionChecked {

	public static void main(String[] args) throws MyException {
		
		Conta c = new Conta();
		try {
			c.deposita();
		} catch (MyException mex) {
			System.out.println("Tratamento de conta com Exception...");
		}
		
	}

}


Agora, esse código compila! Mas pelo fato de deposita() 
jogar uma exceção checked, não tem como fugir! Quem chama o método 
deposita() sabe que ele pode ser perigoso e que pode ocasionar uma exceção. 
Isso não acontece com exceções unchecked.


Agora que que foi visto e estudado as duas categorias de exceções, 
caso você goste de avisar o desenvolvedor que um dia estará usando a sua 
classe, para que ele faça um tratamento, pois algumas exceções podem acabar
ocorrendo, use checked. Se você acha que não precisa disso e que o desenvolvedor
pode fazer o tratamento quando ele achar melhor ou necessário, 
use unchecked.










































































































































































































































































































































































































